Workbook

Sheet Register
A1: ID | B1: Program name | C1: Level | D1: Agency/Funder | E1: Type | F1: Award size (text range) | G1: Direct company access | H1: HCSP output fit | I1: Vertical fit | J1: 2026 Status | K1: Next deadline/cycle | L1: Match score (1-5) | M1: Notes/conditions | N1: Source URL
A2: G-001 | B2: Clean Water SRF (CWSRF) incl. IIJA Emerging Contaminants supplement | C2: Federal | D2: EPA Office of Water -> state SRF programs | E2: Sub-grant via partner | F2: State-set; FY26 ~$746M state allotments + $2.6B IIJA + $225M EC tranche (final IIJA year) | G2: No—via utility partner | H2: Water; Power; PFAS destruction | I2: Municipal biosolids; PFAS concentrate; wastewater reuse | J2: ACTIVE | K2: Rolling; annual state IUPs (summer-fall) | L2: 4 | M2: FY2026 is the final IIJA/BIL supplemental year (incl. $225M CWSRF emerging-contaminants tranche); FY27 House proposal ~16% cut; WRDA 2026 would add emerging-contaminants eligibility. Access via POTW/utility partner on state IUP. | N2: https://www.epa.gov/cwsrf
A3: G-002 | B3: Drinking Water SRF (DWSRF) incl. $4B PFAS/emerging-contaminants funds | C3: Federal | D3: EPA Office of Water -> state SRF programs | E3: Sub-grant via partner | F3: FY26 ~$411M state allotments + ~$3.4B IIJA; $4B PFAS/EC over 5 yrs | G3: No—via utility partner | H3: Water; PFAS destruction | I3: Drinking-water PFAS compliance; small/disadvantaged systems | J3: ACTIVE | K3: Rolling; annual state IUPs | L3: 4 | M3: $4B of DWSRF dedicated to PFAS/emerging contaminants; destruction slots in as residuals management of BAT (GAC/IX/RO) concentrate streams; WRDA 2026 would add explicit PFAS eligibility to DWSRF. | N3: https://www.epa.gov/dwsrf
A4: G-003 | B4: Emerging Contaminants in Small or Disadvantaged Communities (EC-SDC) grants | C4: Federal | D4: EPA -> states/territories | E4: Sub-grant via partner | F4: $5B FY2022-26 total; final $1B announced May 2026 | G4: No—via utility partner | H4: PFAS destruction; Water | I4: Small/disadvantaged community water systems | J4: ACTIVE | K4: State-driven; final BIL allotment year 2026 | L4: 4 | M4: Final $1B year announced May 19 2026 (CA $77.3M, NY $40.5M, NJ $33.6M, AZ $20M); EPA framed the round as supporting innovation in destruction and disposal technologies; company participates as vendor to the water system. | N4: https://www.epa.gov/dwcapacity
A5: G-004 | B5: WIFIA (Water Infrastructure Finance and Innovation Act) + SWIFIA | C5: Federal | D5: EPA | E5: Loan | F5: Loans up to 49% of project costs; $20M min project ($5M small communities); ~$11B credit capacity available | G5: Yes | H5: Water; Power; PFAS destruction | I5: Water reuse; desalination; biosolids-to-energy; alternative supply | J5: ACTIVE | K5: Rolling Letters of Interest, year-round | L5: 5 | M5: Direct private access unusually broad (corporations, JVs, trusts) but private projects need public sponsorship; FY26-27 small-community fee waivers ($25K application + ~$156K credit-processing); statutory authorization expires after FY2026 - WRDA 2026 would extend. | N5: https://www.epa.gov/wifia
A6: G-005 | B6: WaterSMART Title XVI Water Reclamation & Reuse (R26AS00079) | C6: Federal | D6: Bureau of Reclamation | E6: Grant | F6: Ceiling $40M; 25% federal cost share; FY26 competitive pot cut to ~$10M | G6: No—via utility partner | H6: Water | I6: Western water reuse / recycled water | J6: ACTIVE | K6: Deadlines Aug 26 2026 and Aug 26 2027 | L6: 3 | M6: 17 Western states only; applicant must have water or power delivery authority - company partners as technology provider; FY26 appropriations cut 58%, but ~$200M Colorado River Basin reuse investments announced (e.g. $179M Phoenix). | N6: https://www.usbr.gov/watersmart/title/titlexvi.html
A7: G-006 | B7: WaterSMART Desalination Construction Projects (R26AS00034) | C7: Federal | D7: Bureau of Reclamation | E7: Grant | F7: Up to $120M per project | G7: No—via utility partner | H7: Water; Power | I7: Desalination; brine/ZLD; alternative supply | J7: ACTIVE | K7: Due Aug 26 2026 / Aug 26 2027 | L7: 3 | M7: Western states; partner with an eligible water authority; HCSP distilled-water output and energy co-production fit the desalination/purification framing. | N7: https://www.usbr.gov/watersmart/
A8: G-007 | B8: WaterSMART Large-Scale Water Recycling Projects (R25AS00322) | C8: Federal | D8: Bureau of Reclamation | E8: Grant | F8: 25% federal share; projects >=$500M total cost | G8: No—via utility partner | H8: Water | I8: Municipal-scale water recycling | J8: WATCH | K8: FY26 deadline May 13 2026 (closed); watch FY27 NOFO | L8: 2 | M8: Only for very large projects; track the FY27 cycle with a major Western utility partner. | N8: https://www.usbr.gov/watersmart/
A9: G-008 | B9: WaterSMART small grants (WEEG, SWEP, Drought Resiliency, Applied Science, Enhancing Water Resources) | C9: Federal | D9: Bureau of Reclamation | E9: Grant | F9: $100K-$5M tiers; 25-50% cost share; $38.9M WEEG awarded to 31 projects in 2026 | G9: No—via utility partner | H9: Water; Power | I9: Water/energy efficiency at utilities | J9: ACTIVE | K9: Enhancing Water Resources due Sep 9 2026; others re-offer periodically | L9: 2 | M9: WEEG up to $5M (50% cost share); several FY26 deadlines passed; marginal SCWO fit except via efficiency framing; nonprofits may co-apply with a Category A entity. | N9: https://www.usbr.gov/watersmart/
A10: G-009 | B10: Desalination & Water Purification Research (DWPR) NOFO | C10: Federal | D10: Bureau of Reclamation R&D Office | E10: Grant | F10: Lab-scale up to $300K federal; pilot-scale up to $800K federal; $5.7M total FY26 | G10: Yes | H10: Water; PFAS destruction | I10: Produced water; municipal wastewater; impaired waters | J10: OPEN-DEADLINE | K10: Due 4:00 p.m. MT September 29 2026 (posted Jul 29 2026) | L10: 5 | M10: Best near-term direct-apply federal grant: for-profit firms eligible directly; produced water and municipal wastewater are named eligible source waters; ~75% non-federal cost share for pilots; also watch companion Pitch-to-Pilot NOFO (last issued FY2024). | N10: https://www.usbr.gov/research/dwpr/index.html
A11: G-010 | B11: EPA SBIR (Phase I/II contracts) | C11: Federal | D11: EPA | E11: Grant | F11: Phase I ~$100K/6 mo; Phase II up to $400K + $100K commercialization option | G11: Yes | H11: PFAS destruction; Water | I11: PFAS in sludge/biosolids; water reuse; concentrate destruction | J11: WATCH | K11: No Phase I open as of Sept 2026; annual cadence historically Jun-Aug; Phase II (68HERC25R0203) closed Jul 14 2026 | L11: 4 | M11: Reauthorized Apr 13 2026 (S. 3971) through Sept 30 2031 after 6.5-month lapse; recurring water topics include PFAS destruction in wastewater sludge/biosolids; join EPA SBIR listserv and pre-position proposal. | N11: https://www.epa.gov/sbir
A12: G-011 | B12: EPA Office of Water competitive grant programs (OSG stormwater reuse; Midsize/Large DW Resilience; Wastewater Efficiency waste-to-energy; Alternative Water Source pilot) | C12: Federal | D12: EPA Office of Water | E12: Sub-grant via partner | F12: OSG ~$280M/yr authorized; DW resilience first round $9.5M; Wastewater Efficiency <=$4M/recipient; Alternative Water Source $2M FY26 start-up | G12: No—via utility partner | H12: Water; Power | I12: Stormwater/water reuse; POTW biosolids-to-energy; alternative supply | J12: WATCH | K12: Periodic NOFOs; Wastewater Efficiency authorization lapses after FY26 (watch WRDA 2026); Alternative Water Source first solicitation anticipated | L12: 3 | M12: Municipalities/POTWs/water authorities only - company as technology vendor; Wastewater Efficiency Grant Pilot (DWWIA 50202) fits biosolids-to-power but is minimally funded; Alternative Water Source (DWWIA 50203) received first-ever $2M FY26 appropriation. | N12: https://www.epa.gov/cwsrf/sewer-overflow-and-stormwater-reuse-municipal-grants-program
A13: G-012 | B13: EPA STAR / National Priorities research grants | C13: Federal | D13: EPA ORD | E13: Sub-grant via partner | F13: Typically $500K-$1.5M to academic primes | G13: No—via other partner | H13: PFAS destruction; Water | I13: PFAS in landfills/leachates; biosolids; water reuse research | J13: WATCH | K13: No open RFAs as of Aug 2026; RFAs intermittent | L13: 2 | M13: For-profits not eligible as prime; participate as subcontractor on university-led proposals; closed RFAs (PFAS destruction in landfills/leachates, biosolids, reuse) indicate recurring topics. | N13: https://www.epa.gov/research-grants
... A81: G-080 | B81: Breakthrough Energy (Fellows grant; Catalyst FOAK finance; BEV equity) | C81: Private-foundation | D81: Breakthrough Energy | E81: Grant | F81: Innovator Fellowship up to ~$500K/1 yr (pre-venture, <$2M raised); Catalyst first-of-a-kind project scale | G81: Yes | H81: Power; Water | I81: Pre-venture climate tech; first commercial plants | J81: ACTIVE | K81: Annual Fellows cycle (2026 cohort started Sept 2026) | L81: 3 | M81: Mixed instruments: Fellows = grant but only for pre-venture entities; Catalyst relevant later for a first commercial HCSP plant; BEV is equity, not grant; Breakthrough Energy Discovery also anchor-funds Elemental's DCII. | N81: https://breakthroughenergy.org/

Sheet Top 15
A1: Rank | B1: ID | C1: Program name | D1: Level | E1: Agency/Funder | F1: Award size | G1: 2026 Status | H1: Next deadline/cycle | I1: Match score | J1: Why now | K1: Source URL
A2: 1 | B2: =Register!A10 -> G-009 | C2: =IFERROR(INDEX(Register!$B$2:$B$81,MATCH($B2,Register!$A$2:$A$81,0)),"") -> Desalination & Water Purification Research (DWPR) NOFO | D2: =IFERROR(INDEX(Register!$C$2:$C$81,MATCH($B2,Register!$A$2:$A$81,0)),"") -> Federal | E2: =IFERROR(INDEX(Register!$D$2:$D$81,MATCH($B2,Register!$A$2:$A$81,0)),"") -> Bureau of Reclamation R&D Office | F2: =IFERROR(INDEX(Register!$F$2:$F$81,MATCH($B2,Register!$A$2:$A$81,0)),"") -> Lab-scale up to $300K federal; pilot-scale up to $800K federal; $5.7M total FY26 | G2: =IFERROR(INDEX(Register!$J$2:$J$81,MATCH($B2,Register!$A$2:$A$81,0)),"") -> OPEN-DEADLINE | H2: =IFERROR(INDEX(Register!$K$2:$K$81,MATCH($B2,Register!$A$2:$A$81,0)),"") -> Due 4:00 p.m. MT September 29 2026 (posted Jul 29 2026) | I2: =IFERROR(INDEX(Register!$L$2:$L$81,MATCH($B2,Register!$A$2:$A$81,0)),"") -> 5 | J2: Urgency: proposals due 4:00 p.m. MT Sep 29 2026. The single best direct-apply federal grant - for-profits eligible, produced water and municipal wastewater are named source waters, pilot-scale up to $800K. | K2: =IFERROR(INDEX(Register!$N$2:$N$81,MATCH($B2,Register!$A$2:$A$81,0)),"") -> https://www.usbr.gov/research/dwpr/index.html
A3: 2 | B3: =Register!A37 -> G-036 | C3: =IFERROR(INDEX(Register!$B$2:$B$81,MATCH($B3,Register!$A$2:$A$81,0)),"") -> ONR Long-Range BAA N0001425SB001 (Navy & Marine Corps S&T) | D3: =IFERROR(INDEX(Register!$C$2:$C$81,MATCH($B3,Register!$A$2:$A$81,0)),"") -> Federal | E3: =IFERROR(INDEX(Register!$D$2:$D$81,MATCH($B3,Register!$A$2:$A$81,0)),"") -> Office of Naval Research | F3: =IFERROR(INDEX(Register!$F$2:$F$81,MATCH($B3,Register!$A$2:$A$81,0)),"") -> ~$300K-$1M+/yr per effort, negotiated | G3: =IFERROR(INDEX(Register!$J$2:$J$81,MATCH($B3,Register!$A$2:$A$81,0)),"") -> OPEN-DEADLINE | H3: =IFERROR(INDEX(Register!$K$2:$K$81,MATCH($B3,Register!$A$2:$A$81,0)),"") -> Full proposals accepted through September 30 2026; white papers strongly encouraged first | I3: =IFERROR(INDEX(Register!$L$2:$L$81,MATCH($B3,Register!$A$2:$A$81,0)),"") -> 5 | J3: Urgency: BAA N0001425SB001 closes Sep 30 2026. Submit a white paper now (strongly encouraged) on waste-heat SCWO water production; for-profits eligible. | K3: =IFERROR(INDEX(Register!$N$2:$N$81,MATCH($B3,Register!$A$2:$A$81,0)),"") -> https://www.grants.gov/search-results-detail/356605
A4: 3 | B4: =Register!A29 -> G-028 | C4: =IFERROR(INDEX(Register!$B$2:$B$81,MATCH($B4,Register!$A$2:$A$81,0)),"") -> ESTCP demonstration/validation (Installation Energy & Water; Environmental Restoration) | D4: =IFERROR(INDEX(Register!$C$2:$C$81,MATCH($B4,Register!$A$2:$A$81,0)),"") -> Federal | E4: =IFERROR(INDEX(Register!$D$2:$D$81,MATCH($B4,Register!$A$2:$A$81,0)),"") -> ODASD (Energy Resilience & Optimization) | F4: =IFERROR(INDEX(Register!$F$2:$F$81,MATCH($B4,Register!$A$2:$A$81,0)),"") -> ~$0.5M-$3M+ per demonstration (~3 yrs) | G4: =IFERROR(INDEX(Register!$J$2:$J$81,MATCH($B4,Register!$A$2:$A$81,0)),"") -> ACTIVE | H4: =IFERROR(INDEX(Register!$K$2:$K$81,MATCH($B4,Register!$A$2:$A$81,0)),"") -> FY28 solicitations expected ~Dec 2026-Jan 2027, pre-proposals ~Mar 2027 (FY27 in selection Sept 2026) | I4: =IFERROR(INDEX(Register!$L$2:$L$81,MATCH($B4,Register!$A$2:$A$81,0)),"") -> 5 | J4: ESTCP FY28 solicitation expected ~Dec 2026-Mar 2027; FY27 topics already named Water Resilience and Energy Resilience - direct HCSP fits; SCWO precedent ER23-7939; line up a DoD installation demo host now. | K4: =IFERROR(INDEX(Register!$N$2:$N$81,MATCH($B4,Register!$A$2:$A$81,0)),"") -> https://www.serdp-estcp.org/Funding-Opportunities/ESTCP-Solicitations
A5: 4 | B5: =Register!A28 -> G-027 | C5: =IFERROR(INDEX(Register!$B$2:$B$81,MATCH($B5,Register!$A$2:$A$81,0)),"") -> SERDP Core BAA (Strategic Environmental Research and Development Program) | D5: =IFERROR(INDEX(Register!$C$2:$C$81,MATCH($B5,Register!$A$2:$A$81,0)),"") -> Federal | E5: =IFERROR(INDEX(Register!$D$2:$D$81,MATCH($B5,Register!$A$2:$A$81,0)),"") -> OUSD(R&E) / SERDP-ESTCP program office | F5: =IFERROR(INDEX(Register!$F$2:$F$81,MATCH($B5,Register!$A$2:$A$81,0)),"") -> ~$1M-$3M over 3-4 yrs (core); SEED exploratory <=$250K/1 yr | G5: =IFERROR(INDEX(Register!$J$2:$J$81,MATCH($B5,Register!$A$2:$A$81,0)),"") -> WATCH | H5: =IFERROR(INDEX(Register!$K$2:$K$81,MATCH($B5,Register!$A$2:$A$81,0)),"") -> FY28 solicitation expected ~Oct-Nov 2026 (FY27 pre-proposals closed Jan 13 2026) | I5: =IFERROR(INDEX(Register!$L$2:$L$81,MATCH($B5,Register!$A$2:$A$81,0)),"") -> 4 | J5: SERDP FY28 Core BAA expected ~Oct-Nov 2026; direct SCWO PFAS-destruction precedents (ER20-5350, ER22-7338); pre-position for a FY28 Environmental Restoration SON. | K5: =IFERROR(INDEX(Register!$N$2:$N$81,MATCH($B5,Register!$A$2:$A$81,0)),"") -> https://www.serdp-estcp.org/work-with-us
A6: 5 | B6: =Register!A54 -> G-053 | C6: =IFERROR(INDEX(Register!$B$2:$B$81,MATCH($B6,Register!$A$2:$A$81,0)),"") -> NJ PFAS Abatement Fund ($795M) via NJ Water Bank | D6: =IFERROR(INDEX(Register!$C$2:$C$81,MATCH($B6,Register!$A$2:$A$81,0)),"") -> State | E6: =IFERROR(INDEX(Register!$D$2:$D$81,MATCH($B6,Register!$A$2:$A$81,0)),"") -> NJDEP / NJ Water Bank | F6: =IFERROR(INDEX(Register!$F$2:$F$81,MATCH($B6,Register!$A$2:$A$81,0)),"") -> $795M fund; >=$150M to Water Bank for POTWs; >=$90M to counties for AFFF sites; SFY26 IUPs ~$900M clean-water + ~$790M drinking-water baseline | G6: =IFERROR(INDEX(Register!$J$2:$J$81,MATCH($B6,Register!$A$2:$A$81,0)),"") -> ACTIVE | H6: =IFERROR(INDEX(Register!$K$2:$K$81,MATCH($B6,Register!$A$2:$A$81,0)),"") -> Program design rolling out post court approval (Aug 7 2026) - engage now | I6: =IFERROR(INDEX(Register!$L$2:$L$81,MATCH($B6,Register!$A$2:$A$81,0)),"") -> 5 | J6: NJ $795M PFAS Abatement Fund approved Aug 7 2026 - program design forming NOW; >=$150M routed to POTWs via the Water Bank; engage NJDEP/Water Bank while project pipelines form. | K6: =IFERROR(INDEX(Register!$N$2:$N$81,MATCH($B6,Register!$A$2:$A$81,0)),"") -> https://dep.nj.gov/3m/
A7: 6 | B7: =Register!A65 -> G-064 | C7: =IFERROR(INDEX(Register!$B$2:$B$81,MATCH($B7,Register!$A$2:$A$81,0)),"") -> WI Acts 200/201 PFAS grant programs (>$130M) | D7: =IFERROR(INDEX(Register!$C$2:$C$81,MATCH($B7,Register!$A$2:$A$81,0)),"") -> State | E7: =IFERROR(INDEX(Register!$D$2:$D$81,MATCH($B7,Register!$A$2:$A$81,0)),"") -> Wisconsin DNR | F7: =IFERROR(INDEX(Register!$F$2:$F$81,MATCH($B7,Register!$A$2:$A$81,0)),"") -> Community/municipal PFAS grants (~20% match); Airport & Industrial Possessor grants; landfill leachate/biosolids treatment grants; well compensation | G7: =IFERROR(INDEX(Register!$J$2:$J$81,MATCH($B7,Register!$A$2:$A$81,0)),"") -> ACTIVE | H7: =IFERROR(INDEX(Register!$K$2:$K$81,MATCH($B7,Register!$A$2:$A$81,0)),"") -> Launching summer 2026 - winter 2026 (sampling grants first) | I7: =IFERROR(INDEX(Register!$L$2:$L$81,MATCH($B7,Register!$A$2:$A$81,0)),"") -> 5 | J7: WI Acts 200/201 (>$130M, signed Jun 2026) include grants to municipalities AND privately owned landfills for on-site leachate/biosolids treatment - launching summer-fall 2026; most direct state door for a leachate vendor. | K7: =IFERROR(INDEX(Register!$N$2:$N$81,MATCH($B7,Register!$A$2:$A$81,0)),"") -> https://content.govdelivery.com/accounts/WIDNR/bulletins/411b1f6
A8: 7 | B8: =Register!A51 -> G-050 | C8: =IFERROR(INDEX(Register!$B$2:$B$81,MATCH($B8,Register!$A$2:$A$81,0)),"") -> NYSERDA Waste-to-Low-Carbon-Fuels Pilot & Demonstration (+ July 2026 $8M alternative-fuels round) | D8: =IFERROR(INDEX(Register!$C$2:$C$81,MATCH($B8,Register!$A$2:$A$81,0)),"") -> State | E8: =IFERROR(INDEX(Register!$D$2:$D$81,MATCH($B8,Register!$A$2:$A$81,0)),"") -> NYSERDA | F8: =IFERROR(INDEX(Register!$F$2:$F$81,MATCH($B8,Register!$A$2:$A$81,0)),"") -> ~$8M solicitations; >=50% non-NYSERDA cost share; 3-phase pilot->demo structure | G8: =IFERROR(INDEX(Register!$J$2:$J$81,MATCH($B8,Register!$A$2:$A$81,0)),"") -> ACTIVE | H8: =IFERROR(INDEX(Register!$K$2:$K$81,MATCH($B8,Register!$A$2:$A$81,0)),"") -> 2025 solicitation (Aug 2025) + $8M round announced Jul 21 2026 under PSC Innovation & Research Order | I8: =IFERROR(INDEX(Register!$L$2:$L$81,MATCH($B8,Register!$A$2:$A$81,0)),"") -> 4 | J8: NYSERDA waste-to-low-carbon-fuels: $8M round announced Jul 21 2026; wastewater sludge is an explicitly eligible feedstock; private technology providers can lead; >=50% cost share required. | K8: =IFERROR(INDEX(Register!$N$2:$N$81,MATCH($B8,Register!$A$2:$A$81,0)),"") -> https://www.nyserda.ny.gov/
A9: 8 | B9: =Register!A47 -> G-046 | C9: =IFERROR(INDEX(Register!$B$2:$B$81,MATCH($B9,Register!$A$2:$A$81,0)),"") -> AZ WIFA Long-Term Water Augmentation Fund - In-State Water Augmentation cycle | D9: =IFERROR(INDEX(Register!$C$2:$C$81,MATCH($B9,Register!$A$2:$A$81,0)),"") -> State | E9: =IFERROR(INDEX(Register!$D$2:$D$81,MATCH($B9,Register!$A$2:$A$81,0)),"") -> Arizona Water Infrastructure Finance Authority | F9: =IFERROR(INDEX(Register!$F$2:$F$81,MATCH($B9,Register!$A$2:$A$81,0)),"") -> Fund balance ~$376M (post FY26 clawback); awards >$50M require Joint Legislative Water Committee review | G9: =IFERROR(INDEX(Register!$J$2:$J$81,MATCH($B9,Register!$A$2:$A$81,0)),"") -> ACTIVE | H9: =IFERROR(INDEX(Register!$K$2:$K$81,MATCH($B9,Register!$A$2:$A$81,0)),"") -> In-State Water Augmentation funding cycle OPEN since Nov 17 2025 | I9: =IFERROR(INDEX(Register!$L$2:$L$81,MATCH($B9,Register!$A$2:$A$81,0)),"") -> 5 | J9: AZ WIFA In-State Water Augmentation cycle OPEN since Nov 17 2025; private developers can propose within project teams (wastewater-to-drinking-water precedent already selected into Phase-2 funding). | K9: =IFERROR(INDEX(Register!$N$2:$N$81,MATCH($B9,Register!$A$2:$A$81,0)),"") -> https://wifa.az.gov/
A10: 9 | B10: =Register!A55 -> G-054 | C10: =IFERROR(INDEX(Register!$B$2:$B$81,MATCH($B10,Register!$A$2:$A$81,0)),"") -> PA PENNVEST (incl. Growing Greener / Act 13 WRPP as secondary channels) | D10: =IFERROR(INDEX(Register!$C$2:$C$81,MATCH($B10,Register!$A$2:$A$81,0)),"") -> State | E10: =IFERROR(INDEX(Register!$D$2:$D$81,MATCH($B10,Register!$A$2:$A$81,0)),"") -> PENNVEST | F10: =IFERROR(INDEX(Register!$F$2:$F$81,MATCH($B10,Register!$A$2:$A$81,0)),"") -> Up to $11M/project ($20M multi-municipality; board can exceed for regional consolidation); grant + 1.7-2.2% loan blends | G10: =IFERROR(INDEX(Register!$J$2:$J$81,MATCH($B10,Register!$A$2:$A$81,0)),"") -> ACTIVE | H10: =IFERROR(INDEX(Register!$K$2:$K$81,MATCH($B10,Register!$A$2:$A$81,0)),"") -> Rolling applications; quarterly board-meeting cutoffs | I10: =IFERROR(INDEX(Register!$L$2:$L$81,MATCH($B10,Register!$A$2:$A$81,0)),"") -> 5 | J10: PA PENNVEST: rare DIRECT private eligibility (owner/operators), rolling with quarterly board cutoffs; reuse/energy-efficiency/emerging-contaminants tracks all fit. | K10: =IFERROR(INDEX(Register!$N$2:$N$81,MATCH($B10,Register!$A$2:$A$81,0)),"") -> https://dced.pa.gov/programs/pennsylvania-infrastructure-investment-authority-pennvest/
A11: 10 | B11: =Register!A68 -> G-067 | C11: =IFERROR(INDEX(Register!$B$2:$B$81,MATCH($B11,Register!$A$2:$A$81,0)),"") -> Imagine H2O Global Accelerator (incl. Asia track) | D11: =IFERROR(INDEX(Register!$C$2:$C$81,MATCH($B11,Register!$A$2:$A$81,0)),"") -> Private-foundation | E11: =IFERROR(INDEX(Register!$D$2:$D$81,MATCH($B11,Register!$A$2:$A$81,0)),"") -> Imagine H2O | F11: =IFERROR(INDEX(Register!$F$2:$F$81,MATCH($B11,Register!$A$2:$A$81,0)),"") -> Zero-equity; ~$25K non-dilutive award + mentorship/network | G11: =IFERROR(INDEX(Register!$J$2:$J$81,MATCH($B11,Register!$A$2:$A$81,0)),"") -> ACTIVE | H11: =IFERROR(INDEX(Register!$K$2:$K$81,MATCH($B11,Register!$A$2:$A$81,0)),"") -> 2027 cohort applications open November 2026, close December 2026; program Apr-Nov 2027 | I11: =IFERROR(INDEX(Register!$L$2:$L$81,MATCH($B11,Register!$A$2:$A$81,0)),"") -> 5 | J11: Imagine H2O 2027 accelerator applications open Nov-Dec 2026 - zero equity, ~$25K award, and the 2026 cohort confirmed PFAS/sludge-destruction startups in-scope. | K11: =IFERROR(INDEX(Register!$N$2:$N$81,MATCH($B11,Register!$A$2:$A$81,0)),"") -> https://www.imagineh2o.org/apply/
A12: 11 | B12: =Register!A71 -> G-070 | C12: =IFERROR(INDEX(Register!$B$2:$B$81,MATCH($B12,Register!$A$2:$A$81,0)),"") -> Elemental Impact Data Center Innovation Initiative (DCII) + core Strategy/Project Tracks | D12: =IFERROR(INDEX(Register!$C$2:$C$81,MATCH($B12,Register!$A$2:$A$81,0)),"") -> Corporate | E12: =IFERROR(INDEX(Register!$D$2:$D$81,MATCH($B12,Register!$A$2:$A$81,0)),"") -> Elemental Impact (with Amazon, Google, Meta, Microsoft) | F12: =IFERROR(INDEX(Register!$F$2:$F$81,MATCH($B12,Register!$A$2:$A$81,0)),"") -> $500K-$5M per project; up to 10 startups through 2027 (DCII); core tracks case-by-case | G12: =IFERROR(INDEX(Register!$J$2:$J$81,MATCH($B12,Register!$A$2:$A$81,0)),"") -> ACTIVE | H12: =IFERROR(INDEX(Register!$K$2:$K$81,MATCH($B12,Register!$A$2:$A$81,0)),"") -> Rolling through 2027 | I12: =IFERROR(INDEX(Register!$L$2:$L$81,MATCH($B12,Register!$A$2:$A$81,0)),"") -> 5 | J12: Elemental DCII invests $500K-$5M per project (up to 10 startups) through 2027 with Amazon/Google/Meta/Microsoft as collaborators - flagship vehicle for the data-center water+cooling+power story. | K12: =IFERROR(INDEX(Register!$N$2:$N$81,MATCH($B12,Register!$A$2:$A$81,0)),"") -> https://elementalimpact.com/data-center-innovation-initiative/
A13: 12 | B13: =Register!A4 -> G-003 | C13: =IFERROR(INDEX(Register!$B$2:$B$81,MATCH($B13,Register!$A$2:$A$81,0)),"") -> Emerging Contaminants in Small or Disadvantaged Communities (EC-SDC) grants | D13: =IFERROR(INDEX(Register!$C$2:$C$81,MATCH($B13,Register!$A$2:$A$81,0)),"") -> Federal | E13: =IFERROR(INDEX(Register!$D$2:$D$81,MATCH($B13,Register!$A$2:$A$81,0)),"") -> EPA -> states/territories | F13: =IFERROR(INDEX(Register!$F$2:$F$81,MATCH($B13,Register!$A$2:$A$81,0)),"") -> $5B FY2022-26 total; final $1B announced May 2026 | G13: =IFERROR(INDEX(Register!$J$2:$J$81,MATCH($B13,Register!$A$2:$A$81,0)),"") -> ACTIVE | H13: =IFERROR(INDEX(Register!$K$2:$K$81,MATCH($B13,Register!$A$2:$A$81,0)),"") -> State-driven; final BIL allotment year 2026 | I13: =IFERROR(INDEX(Register!$L$2:$L$81,MATCH($B13,Register!$A$2:$A$81,0)),"") -> 4 | J13: EC-SDC final $1B BIL year (May 2026 allotments) - last call to ride BIL emerging-contaminant money via small/disadvantaged water-system partners before the FY27 cliff. | K13: =IFERROR(INDEX(Register!$N$2:$N$81,MATCH($B13,Register!$A$2:$A$81,0)),"") -> https://www.epa.gov/dwcapacity
A14: 13 | B14: =Register!A5 -> G-004 | C14: =IFERROR(INDEX(Register!$B$2:$B$81,MATCH($B14,Register!$A$2:$A$81,0)),"") -> WIFIA (Water Infrastructure Finance and Innovation Act) + SWIFIA | D14: =IFERROR(INDEX(Register!$C$2:$C$81,MATCH($B14,Register!$A$2:$A$81,0)),"") -> Federal | E14: =IFERROR(INDEX(Register!$D$2:$D$81,MATCH($B14,Register!$A$2:$A$81,0)),"") -> EPA | F14: =IFERROR(INDEX(Register!$F$2:$F$81,MATCH($B14,Register!$A$2:$A$81,0)),"") -> Loans up to 49% of project costs; $20M min project ($5M small communities); ~$11B credit capacity available | G14: =IFERROR(INDEX(Register!$J$2:$J$81,MATCH($B14,Register!$A$2:$A$81,0)),"") -> ACTIVE | H14: =IFERROR(INDEX(Register!$K$2:$K$81,MATCH($B14,Register!$A$2:$A$81,0)),"") -> Rolling Letters of Interest, year-round | I14: =IFERROR(INDEX(Register!$L$2:$L$81,MATCH($B14,Register!$A$2:$A$81,0)),"") -> 5 | J14: WIFIA: ~$11B credit capacity, rolling LOIs, direct corporate borrowers allowed with public sponsorship, FY26-27 fee waivers - the deployment-scale financing vehicle. | K14: =IFERROR(INDEX(Register!$N$2:$N$81,MATCH($B14,Register!$A$2:$A$81,0)),"") -> https://www.epa.gov/wifia
A15: 14 | B15: =Register!A49 -> G-048 | C15: =IFERROR(INDEX(Register!$B$2:$B$81,MATCH($B15,Register!$A$2:$A$81,0)),"") -> FL CWSRF + BIL emerging-contaminants grants (Orlando/374Water template) | D15: =IFERROR(INDEX(Register!$C$2:$C$81,MATCH($B15,Register!$A$2:$A$81,0)),"") -> State | E15: =IFERROR(INDEX(Register!$D$2:$D$81,MATCH($B15,Register!$A$2:$A$81,0)),"") -> Florida DEP | F15: =IFERROR(INDEX(Register!$F$2:$F$81,MATCH($B15,Register!$A$2:$A$81,0)),"") -> ~$800K demo precedent; full-scale follow-ons $3M-$5M | G15: =IFERROR(INDEX(Register!$J$2:$J$81,MATCH($B15,Register!$A$2:$A$81,0)),"") -> ACTIVE | H15: =IFERROR(INDEX(Register!$K$2:$K$81,MATCH($B15,Register!$A$2:$A$81,0)),"") -> Rolling/annual via FL DEP | I15: =IFERROR(INDEX(Register!$L$2:$L$81,MATCH($B15,Register!$A$2:$A$81,0)),"") -> 5 | J15: FL CWSRF/BIL-EC: the proven Orlando template (utility grant -> demo -> 5-yr license -> $3-5M PFAS hub); replicate now with FL utilities via rolling SRF. | K15: =IFERROR(INDEX(Register!$N$2:$N$81,MATCH($B15,Register!$A$2:$A$81,0)),"") -> https://floridadep.gov/wra
A16: 15 | B16: =Register!A31 -> G-030 | C16: =IFERROR(INDEX(Register!$B$2:$B$81,MATCH($B16,Register!$A$2:$A$81,0)),"") -> DoW SBIR/STTR FY27 releases (all components via DSIP; incl. Army Applied SBIR) | D16: =IFERROR(INDEX(Register!$C$2:$C$81,MATCH($B16,Register!$A$2:$A$81,0)),"") -> Federal | E16: =IFERROR(INDEX(Register!$D$2:$D$81,MATCH($B16,Register!$A$2:$A$81,0)),"") -> DoW (defensesolutions.gov) / Army Futures Command | F16: =IFERROR(INDEX(Register!$F$2:$F$81,MATCH($B16,Register!$A$2:$A$81,0)),"") -> Phase I ~$250K (Navy up to $315K); Phase II $1.7M-$2.0M; Phase III uncapped (non-SBIR funds) | G16: =IFERROR(INDEX(Register!$J$2:$J$81,MATCH($B16,Register!$A$2:$A$81,0)),"") -> ACTIVE | H16: =IFERROR(INDEX(Register!$K$2:$K$81,MATCH($B16,Register!$A$2:$A$81,0)),"") -> FY27 Release 1 pre-release expected ~Oct 2026; quarterly closes (FY26 R4 closed Aug 19 2026); Army runs 3 windows/FY | I16: =IFERROR(INDEX(Register!$L$2:$L$81,MATCH($B16,Register!$A$2:$A$81,0)),"") -> 4 | J16: DoW SBIR FY27 Release 1 pre-release expected ~Oct 2026; quarterly cadence restarted post-reauthorization; watch NAVFAC water/PFAS topics - N254-123/N233-117 lineage gives a Phase II/D2P2 entry. | K16: =IFERROR(INDEX(Register!$N$2:$N$81,MATCH($B16,Register!$A$2:$A$81,0)),"") -> https://www.defensesolutions.gov/

Sheet Dashboard
A1: HCSP Grants Database - Dashboard
A2: All counts computed live from the Register sheet (COUNTIF/COUNTIFS). Award-pool figures are sourced external data (see Source column).
A4: Programs by Level
A5: Category | B5: Count
A6: Federal | B6: =COUNTIF(Register!$C$2:$C$81,"Federal") -> 38
A7: State | B7: =COUNTIF(Register!$C$2:$C$81,"State") -> 23
A8: Municipal-utility | B8: =COUNTIF(Register!$C$2:$C$81,"Municipal-utility") -> 3
A9: Private-foundation | B9: =COUNTIF(Register!$C$2:$C$81,"Private-foundation") -> 12
A10: Corporate | B10: =COUNTIF(Register!$C$2:$C$81,"Corporate") -> 4
A11: TOTAL | B11: =SUM(B6:B10) -> 80
A13: Programs by 2026 Status
A14: Category | B14: Count
A15: ACTIVE | B15: =COUNTIF(Register!$J$2:$J$81,"ACTIVE") -> 57
A16: OPEN-DEADLINE | B16: =COUNTIF(Register!$J$2:$J$81,"OPEN-DEADLINE") -> 2
A17: PAUSED | B17: =COUNTIF(Register!$J$2:$J$81,"PAUSED") -> 1
A18: WATCH | B18: =COUNTIF(Register!$J$2:$J$81,"WATCH") -> 17
A19: DEAD | B19: =COUNTIF(Register!$J$2:$J$81,"DEAD") -> 3
A20: TOTAL | B20: =SUM(B15:B19) -> 80
A22: Programs by Match score
A23: Category | B23: Count
A24: 5 | B24: =COUNTIF(Register!$L$2:$L$81,5) -> 12
A25: 4 | B25: =COUNTIF(Register!$L$2:$L$81,4) -> 24
A26: 3 | B26: =COUNTIF(Register!$L$2:$L$81,3) -> 27
A27: 2 | B27: =COUNTIF(Register!$L$2:$L$81,2) -> 12
A28: 1 | B28: =COUNTIF(Register!$L$2:$L$81,1) -> 5
A29: TOTAL | B29: =SUM(B24:B28) -> 80
A31: Direct company access
A32: Category | B32: Count
A33: Yes | B33: =COUNTIF(Register!$G$2:$G$81,"Yes") -> 41
A34: No | B34: =COUNTIF(Register!$G$2:$G$81,"No") -> 3
A35: No—via utility partner | B35: =COUNTIF(Register!$G$2:$G$81,"No—via utility partner") -> 25
A36: No—via other partner | B36: =COUNTIF(Register!$G$2:$G$81,"No—via other partner") -> 11
A37: TOTAL | B37: =SUM(B33:B36) -> 80
A39: Priority cross-cut
A40: Cut | B40: Count
A41: Active/open now AND match >= 4 | B41: =COUNTIFS(Register!$J$2:$J$81,"ACTIVE",Register!$L$2:$L$81,">=4")+COUNTIFS(Register!$J$2:$J$81,"OPEN-DEADLINE",Register!$L$2:$L$81,">=4") -> 33
A42: Direct access (Yes) AND match >= 4 | B42: =COUNTIFS(Register!$G$2:$G$81,"Yes",Register!$L$2:$L$81,">=4") -> 22
A43: DEAD programs (kept for completeness) | B43: =COUNTIF(Register!$J$2:$J$81,"DEAD") -> 3
A46: Known addressable award pools (US$, where disclosed - not exhaustive; includes loans & settlement funds)
A47: Pool | B47: Amount (US$) | C47: Mechanism | D47: Source (research file)
...

Sheet Legend
A1: Legend & Methodology
A3: SECTION | B3: TERM | C3: DEFINITION
A4: Level | B4: Federal | C4: US federal agency program (incl. non-US national schemes where noted).
A5: Level | B5: State | C5: US state agency / state financing authority program.
A6: Level | B6: Municipal-utility | C6: Utility- or municipally-run innovation/pilot program.
A7: Level | B7: Private-foundation | C7: Philanthropic, settlement-administered, or nonprofit-intermediary program.
A8: Level | B8: Corporate | C8: Corporate-funded investment, offtake, or industry-consortium program.
A9: Type | B9: Grant | C9: Non-repayable award (incl. cooperative agreements, contracts-as-grants such as SBIR, and tax credits flagged in notes).
A10: Type | B10: Sub-grant via partner | C10: Funds flow to an eligible public/utility/nonprofit applicant; HCSP participates as technology vendor or subrecipient.
A11: Type | B11: Loan | C11: Below-market debt financing (e.g. WIFIA, SRF, PENNVEST, SWIFT).
A12: Type | B12: Loan guarantee | C12: Federal guarantee of commercial debt (REAP loans, B&I, Title 17).
A13: Type | B13: Prize | C13: Competitive prize award.
A14: Type | B14: Accelerator | C14: Cohort program; may include small award; zero- or low-cost.
... A33: Methodology | B33: Known gaps | C33: Maine $50M bond vote outcome unconfirmed; CA has no cannabis-wastewater grant program; HI has no state innovation grant beyond SRF/NELHA; OH/WV have no distinct produced-water grant programs; Brewers Association/DISCUS have no grant programs; Greentown ACCEL possibly dormant; aggregator-sourced items should be confirmed on official sites.
